<sdf version='1.7'>
  <model name='racecar'>
    <link name='base_footprint'>
      <inertial>
        <pose>-0.006516 0 0.104055 0 -0 0</pose>
        <mass>3.802</mass>
        <inertia>
          <ixx>0.0193</ixx>
          <ixy>-3.5325e-22</ixy>
          <ixz>4.72039e-05</ixz>
          <iyy>0.0274234</iyy>
          <iyz>-1.86734e-22</iyz>
          <izz>0.0373702</izz>
        </inertia>
      </inertial>
      <collision name='base_footprint_fixed_joint_lump__chassis_collision'>
        <pose>0 0 0.1025 0 -0 0</pose>
        <geometry>
          <box>
            <size>0.258 0.168 0.01</size>
          </box>
        </geometry>
        <surface>
          <contact>
            <ode/>
          </contact>
          <friction>
            <ode/>
          </friction>
        </surface>
      </collision>
      <collision name='base_footprint_fixed_joint_lump__left_battery_collision_1'>
        <pose>-0.025 0.057319 0.10802 0.349066 -0 0</pose>
        <geometry>
          <box>
            <size>0.16 0.047 0.024</size>
          </box>
        </geometry>
        <surface>
          <contact>
            <ode/>
          </contact>
          <friction>
            <ode/>
          </friction>
        </surface>
      </collision>
      <collision name='base_footprint_fixed_joint_lump__right_battery_collision_2'>
        <pose>-0.025 -0.057319 0.10802 -0.349066 0 0</pose>
        <geometry>
          <box>
            <size>0.16 0.047 0.024</size>
          </box>
        </geometry>
        <surface>
          <contact>
            <ode/>
          </contact>
          <friction>
            <ode/>
          </friction>
        </surface>
      </collision>
      <collision name='base_footprint_fixed_joint_lump__platform_link_collision_3'>
        <pose>0 0 0.1875 0 -0 0</pose>
        <geometry>
          <box>
            <size>0.4 0.18 0.01</size>
          </box>
        </geometry>
        <surface>
          <contact>
            <ode/>
          </contact>
          <friction>
            <ode/>
          </friction>
        </surface>
      </collision>
      <collision name='base_footprint_fixed_joint_lump__camera_link_collision_4'>
        <pose>0.16 0 0.2375 0 -0 0</pose>
        <geometry>
          <box>
            <size>0.03 0.16 0.03</size>
          </box>
        </geometry>
        <surface>
          <contact>
            <ode/>
          </contact>
          <friction>
            <ode/>
          </friction>
        </surface>
      </collision>
      <collision name='base_footprint_fixed_joint_lump__imu_link_collision_5'>
        <pose>0.16 0 0.2025 0 -0 0</pose>
        <geometry>
          <box>
            <size>0.04 0.04 0.03</size>
          </box>
        </geometry>
        <surface>
          <contact>
            <ode/>
          </contact>
          <friction>
            <ode/>
          </friction>
        </surface>
      </collision>
      <collision name='base_footprint_fixed_joint_lump__lidar_platform_link_collision_6'>
        <pose>0.08 0 0.2675 0 -0 0</pose>
        <geometry>
          <box>
            <size>0.12 0.1 0.01</size>
          </box>
        </geometry>
        <surface>
          <contact>
            <ode/>
          </contact>
          <friction>
            <ode/>
          </friction>
        </surface>
      </collision>
      <collision name='base_footprint_fixed_joint_lump__laser_link_collision_7'>
        <pose>0.08 0 0.2975 0 -0 0</pose>
        <geometry>
          <cylinder>
            <length>0.06</length>
            <radius>0.05</radius>
          </cylinder>
        </geometry>
        <surface>
          <contact>
            <ode/>
          </contact>
          <friction>
            <ode/>
          </friction>
        </surface>
      </collision>
      <visual name='base_footprint_fixed_joint_lump__base_link_visual'>
        <pose>0 0 0.1075 0 -0 0</pose>
        <geometry>
          <box>
            <size>0.01 0.01 0.01</size>
          </box>
        </geometry>
        <material>
          <script>
            <name>Gazebo/Grey</name>
            <uri>file://media/materials/scripts/gazebo.material</uri>
          </script>
        </material>
      </visual>
      <visual name='base_footprint_fixed_joint_lump__chassis_visual_1'>
        <pose>0 0 0.1025 0 -0 0</pose>
        <geometry>
          <box>
            <size>0.258 0.168 0.01</size>
          </box>
        </geometry>
        <material>
          <script>
            <name>Gazebo/Grey</name>
            <uri>file://media/materials/scripts/gazebo.material</uri>
          </script>
        </material>
      </visual>
      <visual name='base_footprint_fixed_joint_lump__left_battery_visual_2'>
        <pose>-0.025 0.057319 0.10802 0.349066 -0 0</pose>
        <geometry>
          <box>
            <size>0.16 0.047 0.024</size>
          </box>
        </geometry>
        <material>
          <script>
            <name>Gazebo/Blue</name>
            <uri>file://media/materials/scripts/gazebo.material</uri>
          </script>
        </material>
      </visual>
      <visual name='base_footprint_fixed_joint_lump__right_battery_visual_3'>
        <pose>-0.025 -0.057319 0.10802 -0.349066 0 0</pose>
        <geometry>
          <box>
            <size>0.16 0.047 0.024</size>
          </box>
        </geometry>
        <material>
          <script>
            <name>Gazebo/Blue</name>
            <uri>file://media/materials/scripts/gazebo.material</uri>
          </script>
        </material>
      </visual>
      <visual name='base_footprint_fixed_joint_lump__platform_link_visual_4'>
        <pose>0 0 0.1875 0 -0 0</pose>
        <geometry>
          <box>
            <size>0.4 0.18 0.01</size>
          </box>
        </geometry>
        <material>
          <script>
            <name>Gazebo/Orange</name>
            <uri>file://media/materials/scripts/gazebo.material</uri>
          </script>
        </material>
      </visual>
      <visual name='base_footprint_fixed_joint_lump__camera_link_visual_5'>
        <pose>0.16 0 0.2375 1.57 -0 1.57</pose>
        <geometry>
          <mesh>
            <scale>0.1 0.1 0.1</scale>
            <uri>model://nav2_bringup/meshes/racecar/S1030-0315.dae</uri>
          </mesh>
        </geometry>
        <material>
          <script>
            <name>Gazebo/Black</name>
            <uri>file://media/materials/scripts/gazebo.material</uri>
          </script>
        </material>
      </visual>
      <visual name='base_footprint_fixed_joint_lump__imu_link_visual_6'>
        <pose>0.16 0 0.2025 0 -0 0</pose>
        <geometry>
          <box>
            <size>0.04 0.04 0.03</size>
          </box>
        </geometry>
        <material>
          <script>
            <name>Gazebo/Black</name>
            <uri>file://media/materials/scripts/gazebo.material</uri>
          </script>
        </material>
      </visual>
      <visual name='base_footprint_fixed_joint_lump__lidar_platform_link_visual_7'>
        <pose>0.08 0 0.2675 0 -0 0</pose>
        <geometry>
          <box>
            <size>0.12 0.1 0.01</size>
          </box>
        </geometry>
        <material>
          <script>
            <name>Gazebo/Orange</name>
            <uri>file://media/materials/scripts/gazebo.material</uri>
          </script>
        </material>
      </visual>
      <visual name='base_footprint_fixed_joint_lump__laser_link_visual_8'>
        <pose>0.08 0 0.2975 0 -0 0</pose>
        <geometry>
          <cylinder>
            <length>0.05</length>
            <radius>0.05</radius>
          </cylinder>
        </geometry>
        <material>
          <script>
            <name>Gazebo/Black</name>
            <uri>file://media/materials/scripts/gazebo.material</uri>
          </script>
        </material>
      </visual>
      <sensor name='camera_node' type='camera'>
        <update_rate>30</update_rate>
        <camera name='head'>
          <horizontal_fov>1.39626</horizontal_fov>
          <image>
            <width>1280</width>
            <height>720</height>
            <format>R8G8B8</format>
          </image>
          <clip>
            <near>0.02</near>
            <far>300</far>
          </clip>
          <noise>
            <type>gaussian</type>
            <mean>0</mean>
            <stddev>0.007</stddev>
          </noise>
        </camera>
        <plugin name='gazebo_camera' filename='libgazebo_ros_camera.so'>
          <alwaysOn>1</alwaysOn>
          <updateRate>0.0</updateRate>
          <cameraName>/camera</cameraName>
          <imageTopicName>image_raw</imageTopicName>
          <cameraInfoTopicName>camera_info</cameraInfoTopicName>
          <frameName>camera_link</frameName>
          <hackBaseline>0.07</hackBaseline>
          <distortionK1>0.0</distortionK1>
          <distortionK2>0.0</distortionK2>
          <distortionK3>0.0</distortionK3>
          <distortionT1>0.0</distortionT1>
          <distortionT2>0.0</distortionT2>
        </plugin>
        <pose>0.16 0 0.2375 0 -0 0</pose>
      </sensor>
      <gravity>1</gravity>
      <sensor name='imu_sensor' type='imu'>
        <always_on>1</always_on>
        <update_rate>100</update_rate>
        <visualize>1</visualize>
        <topic>/imu_data</topic>
        <plugin name='imu_plugin' filename='libgazebo_ros_imu_sensor.so'>
          <topicName>/imu_data</topicName>
          <bodyName>imu_link</bodyName>
          <updateRateHZ>100.0</updateRateHZ>
          <gaussianNoise>0.0</gaussianNoise>
          <xyzOffset>0 0 0</xyzOffset>
          <rpyOffset>0 0 0</rpyOffset>
          <frameName>imu_link</frameName>
        </plugin>
        <pose>0.16 0 0.2025 0 -0 0</pose>
      </sensor>
      <sensor name='ls01g' type='ray'>
        <visualize>0</visualize>
        <update_rate>10</update_rate>
        <ray>
          <scan>
            <horizontal>
              <samples>360</samples>
              <resolution>1</resolution>
              <min_angle>-3.14159</min_angle>
              <max_angle>3.14159</max_angle>
            </horizontal>
          </scan>
          <range>
            <min>0.1</min>
            <max>8</max>
            <resolution>0.01</resolution>
          </range>
          <noise>
            <type>gaussian</type>
            <mean>0</mean>
            <stddev>0.01</stddev>
          </noise>
        </ray>
        <plugin name='gazebo_ls01g' filename='libgazebo_ros_laser.so'>
          <topicName>/scan</topicName>
          <frameName>laser_link</frameName>
        </plugin>
        <pose>0.08 0 0.2975 0 -0 0</pose>
      </sensor>
    </link>
    <joint name='left_steering_joint' type='revolute'>
      <pose relative_to='base_footprint'>0.1675 0.1525 0.084 0 -0 0</pose>
      <parent>base_footprint</parent>
      <child>left_front_axle_carrier</child>
      <axis>
        <xyz>0 0 1</xyz>
        <limit>
          <lower>-0.785398</lower>
          <upper>0.785398</upper>
          <effort>0.5649</effort>
          <velocity>4.553</velocity>
        </limit>
        <dynamics>
          <spring_reference>0</spring_reference>
          <spring_stiffness>0</spring_stiffness>
        </dynamics>
      </axis>
    </joint>
    <link name='left_front_axle_carrier'>
      <pose relative_to='left_steering_joint'>0 0 0 0 -0 0</pose>
      <inertial>
        <pose>0 0 0 0 -0 0</pose>
        <mass>0.001</mass>
        <inertia>
          <ixx>0.001</ixx>
          <ixy>0</ixy>
          <ixz>0</ixz>
          <iyy>0.001</iyy>
          <iyz>0</iyz>
          <izz>0.001</izz>
        </inertia>
      </inertial>
    </link>
    <joint name='left_front_axle' type='revolute'>
      <pose relative_to='left_front_axle_carrier'>0 0 0 1.5708 -0 0</pose>
      <parent>left_front_axle_carrier</parent>
      <child>left_front_wheel</child>
      <axis>
        <xyz>0 0 -1</xyz>
        <limit>
          <effort>5.12766</effort>
          <velocity>244.87</velocity>
          <lower>-1e+16</lower>
          <upper>1e+16</upper>
        </limit>
        <dynamics>
          <spring_reference>0</spring_reference>
          <spring_stiffness>0</spring_stiffness>
        </dynamics>
      </axis>
    </joint>
    <link name='left_front_wheel'>
      <pose relative_to='left_front_axle'>0 0 0 0 -0 0</pose>
      <inertial>
        <pose>0 0 0 0 -0 0</pose>
        <mass>0.29</mass>
        <inertia>
          <ixx>0.000746466</ixx>
          <ixy>0</ixy>
          <ixz>0</ixz>
          <iyy>0.000746466</iyy>
          <iyz>0</iyz>
          <izz>0.00111094</izz>
        </inertia>
      </inertial>
      <collision name='left_front_wheel_collision'>
        <pose>0 -0 0 0 -0 0</pose>
        <geometry>
          <cylinder>
            <length>0.0889</length>
            <radius>0.073025</radius>
          </cylinder>
        </geometry>
        <surface>
          <contact>
            <ode/>
          </contact>
          <friction>
            <ode/>
          </friction>
        </surface>
      </collision>
      <visual name='left_front_wheel_visual'>
        <pose>0 -0 0 0 -0 0</pose>
        <geometry>
          <cylinder>
            <length>0.0889</length>
            <radius>0.073025</radius>
          </cylinder>
        </geometry>
        <material>
          <script>
            <name>Gazebo/Black</name>
            <uri>file://media/materials/scripts/gazebo.material</uri>
          </script>
        </material>
      </visual>
    </link>
    <joint name='left_rear_axle' type='revolute'>
      <pose relative_to='base_footprint'>-0.1675 0.1525 0.084 1.5708 -0 0</pose>
      <parent>base_footprint</parent>
      <child>left_rear_wheel</child>
      <axis>
        <xyz>0 0 -1</xyz>
        <limit>
          <effort>5.12766</effort>
          <velocity>244.87</velocity>
          <lower>-1e+16</lower>
          <upper>1e+16</upper>
        </limit>
        <dynamics>
          <spring_reference>0</spring_reference>
          <spring_stiffness>0</spring_stiffness>
        </dynamics>
      </axis>
    </joint>
    <link name='left_rear_wheel'>
      <pose relative_to='left_rear_axle'>0 0 0 0 -0 0</pose>
      <inertial>
        <pose>0 0 0 0 -0 0</pose>
        <mass>0.29</mass>
        <inertia>
          <ixx>0.000746466</ixx>
          <ixy>0</ixy>
          <ixz>0</ixz>
          <iyy>0.000746466</iyy>
          <iyz>0</iyz>
          <izz>0.00111094</izz>
        </inertia>
      </inertial>
      <collision name='left_rear_wheel_collision'>
        <pose>0 -0 0 0 -0 0</pose>
        <geometry>
          <cylinder>
            <length>0.0889</length>
            <radius>0.073025</radius>
          </cylinder>
        </geometry>
        <surface>
          <contact>
            <ode/>
          </contact>
          <friction>
            <ode/>
          </friction>
        </surface>
      </collision>
      <visual name='left_rear_wheel_visual'>
        <pose>0 -0 0 0 -0 0</pose>
        <geometry>
          <cylinder>
            <length>0.0889</length>
            <radius>0.073025</radius>
          </cylinder>
        </geometry>
        <material>
          <script>
            <name>Gazebo/Black</name>
            <uri>file://media/materials/scripts/gazebo.material</uri>
          </script>
        </material>
      </visual>
    </link>
    <joint name='right_steering_joint' type='revolute'>
      <pose relative_to='base_footprint'>0.1675 -0.1525 0.084 0 -0 0</pose>
      <parent>base_footprint</parent>
      <child>right_front_axle_carrier</child>
      <axis>
        <xyz>0 0 1</xyz>
        <limit>
          <lower>-0.785398</lower>
          <upper>0.785398</upper>
          <effort>0.5649</effort>
          <velocity>4.553</velocity>
        </limit>
        <dynamics>
          <spring_reference>0</spring_reference>
          <spring_stiffness>0</spring_stiffness>
        </dynamics>
      </axis>
    </joint>
    <link name='right_front_axle_carrier'>
      <pose relative_to='right_steering_joint'>0 0 0 0 -0 0</pose>
      <inertial>
        <pose>0 0 0 0 -0 0</pose>
        <mass>0.001</mass>
        <inertia>
          <ixx>0.001</ixx>
          <ixy>0</ixy>
          <ixz>0</ixz>
          <iyy>0.001</iyy>
          <iyz>0</iyz>
          <izz>0.001</izz>
        </inertia>
      </inertial>
    </link>
    <joint name='right_front_axle' type='revolute'>
      <pose relative_to='right_front_axle_carrier'>0 0 0 1.5708 -0 0</pose>
      <parent>right_front_axle_carrier</parent>
      <child>right_front_wheel</child>
      <axis>
        <xyz>0 0 -1</xyz>
        <limit>
          <effort>5.12766</effort>
          <velocity>244.87</velocity>
          <lower>-1e+16</lower>
          <upper>1e+16</upper>
        </limit>
        <dynamics>
          <spring_reference>0</spring_reference>
          <spring_stiffness>0</spring_stiffness>
        </dynamics>
      </axis>
    </joint>
    <link name='right_front_wheel'>
      <pose relative_to='right_front_axle'>0 0 0 0 -0 0</pose>
      <inertial>
        <pose>0 0 0 0 -0 0</pose>
        <mass>0.29</mass>
        <inertia>
          <ixx>0.000746466</ixx>
          <ixy>0</ixy>
          <ixz>0</ixz>
          <iyy>0.000746466</iyy>
          <iyz>0</iyz>
          <izz>0.00111094</izz>
        </inertia>
      </inertial>
      <collision name='right_front_wheel_collision'>
        <pose>0 0 0 0 -0 0</pose>
        <geometry>
          <cylinder>
            <length>0.0889</length>
            <radius>0.073025</radius>
          </cylinder>
        </geometry>
        <surface>
          <contact>
            <ode/>
          </contact>
          <friction>
            <ode/>
          </friction>
        </surface>
      </collision>
      <visual name='right_front_wheel_visual'>
        <pose>0 0 0 0 -0 0</pose>
        <geometry>
          <cylinder>
            <length>0.0889</length>
            <radius>0.073025</radius>
          </cylinder>
        </geometry>
        <material>
          <script>
            <name>Gazebo/Black</name>
            <uri>file://media/materials/scripts/gazebo.material</uri>
          </script>
        </material>
      </visual>
    </link>
    <joint name='right_rear_axle' type='revolute'>
      <pose relative_to='base_footprint'>-0.1675 -0.1525 0.084 1.5708 -0 0</pose>
      <parent>base_footprint</parent>
      <child>right_rear_wheel</child>
      <axis>
        <xyz>0 0 -1</xyz>
        <limit>
          <effort>5.12766</effort>
          <velocity>244.87</velocity>
          <lower>-1e+16</lower>
          <upper>1e+16</upper>
        </limit>
        <dynamics>
          <spring_reference>0</spring_reference>
          <spring_stiffness>0</spring_stiffness>
        </dynamics>
      </axis>
    </joint>
    <link name='right_rear_wheel'>
      <pose relative_to='right_rear_axle'>0 0 0 0 -0 0</pose>
      <inertial>
        <pose>0 0 0 0 -0 0</pose>
        <mass>0.29</mass>
        <inertia>
          <ixx>0.000746466</ixx>
          <ixy>0</ixy>
          <ixz>0</ixz>
          <iyy>0.000746466</iyy>
          <iyz>0</iyz>
          <izz>0.00111094</izz>
        </inertia>
      </inertial>
      <collision name='right_rear_wheel_collision'>
        <pose>0 0 0 0 -0 0</pose>
        <geometry>
          <cylinder>
            <length>0.0889</length>
            <radius>0.073025</radius>
          </cylinder>
        </geometry>
        <surface>
          <contact>
            <ode/>
          </contact>
          <friction>
            <ode/>
          </friction>
        </surface>
      </collision>
      <visual name='right_rear_wheel_visual'>
        <pose>0 0 0 0 -0 0</pose>
        <geometry>
          <cylinder>
            <length>0.0889</length>
            <radius>0.073025</radius>
          </cylinder>
        </geometry>
        <material>
          <script>
            <name>Gazebo/Black</name>
            <uri>file://media/materials/scripts/gazebo.material</uri>
          </script>
        </material>
      </visual>
    </link>
  </model>
</sdf>
