<?xml version="1.0" ?>

<robot name="racecar">
  <!-- base footprint -->
  <link name="base_footprint"/>

  <!-- base_link -->
  <link name="base_link">
    <visual>
      <origin xyz="0 0 0.04"/>
      <geometry>
        <box size="0.1 0.1 0.02"/>
      </geometry>
    </visual>
    <collision>
      <origin xyz="0 0 0.04"/>
      <geometry>
        <box size="0.1 0.1 0.02"/>
      </geometry>
    </collision>
    <inertial>
      <origin xyz="0 0 0.04"/>
      <mass value="100"/>
      <inertia ixx="0.001" ixy="0.0" ixz="0.0" iyy="0.001" iyz="0.0" izz="0.001" />
    </inertial>
  </link>
  <joint name="base_joint" type="fixed">
    <parent link="base_footprint"/>
    <child link="base_link"/>
    <origin xyz="0 0 0.04" rpy="0 0 0"/>
  </joint>

  <!-- left front wheel link -->
  <!-- <link name="left_front_wheel">
    <inertial>
      <mass value="1.0"/>
      <inertia ixx="0.001" ixy="0.0" ixz="0.0" iyy="0.001" iyz="0.0" izz="0.001" />
    </inertial>
  </link>
  <joint name="left_front_wheel_joint" type="continuous">
    <parent link="left_front_axle"/>
    <child link="left_front_wheel"/>
    <origin rpy="0 0 0" xyz="0.13 0.08 0.04"/>
    <axis xyz="0 1 0"/>
  </joint>
  <link name="left_front_axle">
    <inertial>
      <origin xyz="0.13 0.08 0.04" rpy="0 0 0"/>
      <mass value="0.1"/>
      <inertia ixx="0.001" ixy="0.0" ixz="0.0" iyy="0.001" iyz="0.0" izz="0.001" />
    </inertial>
  </link>
  <joint name="left_steering_joint" type="continuous">
    <parent link="left_steering"/>
    <child link="left_front_axle"/>
    <origin rpy="0 0 0" xyz="0.13 0.08 0.05"/>
    <axis xyz="0 0 1"/>
  </joint>
  <link name="left_steering">
    <inertial>
      <origin xyz="0.13 0.08 0.05" rpy="0 0 0"/>
      <mass value="0.1"/>
      <inertia ixx="0.001" ixy="0.0" ixz="0.0" iyy="0.001" iyz="0.0" izz="0.001" />
    </inertial>
  </link>
  <joint name="left_joint" type="fixed">
    <parent link="base_link"/>
    <child link="left_steering"/>
    <origin rpy="0 0 0" xyz="0.13 0.08 0.05"/>
  </joint> -->

  <!-- right front wheel link -->
  <!-- <link name="right_front_wheel">
    <inertial>
      <mass value="1.0"/>
      <inertia ixx="0.001" ixy="0.0" ixz="0.0" iyy="0.001" iyz="0.0" izz="0.001" />
    </inertial>
  </link>
  <joint name="right_front_wheel_joint" type="continuous">
    <parent link="right_front_axle"/>
    <child link="right_front_wheel"/>
    <origin rpy="0 0 0" xyz="0.13 -0.08 0.04"/>
    <axis xyz="0 1 0"/>
  </joint>
  <link name="right_front_axle">
    <inertial>
      <origin xyz="0.13 -0.08 0.04" rpy="0 0 0"/>
      <mass value="0.1"/>
      <inertia ixx="0.001" ixy="0.0" ixz="0.0" iyy="0.001" iyz="0.0" izz="0.001" />
    </inertial>
  </link>
  <joint name="right_steering_joint" type="continuous">
    <parent link="right_steering"/>
    <child link="right_front_axle"/>
    <origin rpy="0 0 0" xyz="0.13 -0.08 0.05"/>
    <axis xyz="0 0 1"/>
  </joint>
  <link name="right_steering">
    <inertial>
      <origin xyz="0.13 -0.08 0.05" rpy="0 0 0"/>
      <mass value="0.1"/>
      <inertia ixx="0.001" ixy="0.0" ixz="0.0" iyy="0.001" iyz="0.0" izz="0.001" />
    </inertial>
  </link>
  <joint name="right_joint" type="fixed">
    <parent link="base_link"/>
    <child link="right_steering"/>
    <origin rpy="0 0 0" xyz="0.13 -0.08 0.05"/>
  </joint> -->

  <!-- left rear wheel link -->
  <link name="left_rear_wheel">
    <inertial>
      <mass value="1.0"/>
      <inertia ixx="0.001" ixy="0.0" ixz="0.0" iyy="0.001" iyz="0.0" izz="0.001" />
    </inertial>
  </link>
  <joint name="left_rear_wheel_joint" type="continuous">
    <parent link="base_link"/>
    <child link="left_rear_wheel"/>
    <origin rpy="0 0 0" xyz="-0.13 0.08 0.04"/>
    <axis xyz="0 1 0"/>
  </joint>

  <!-- right rear wheel link -->
  <link name="right_rear_wheel">
    <inertial>
      <mass value="1.0"/>
      <inertia ixx="0.001" ixy="0.0" ixz="0.0" iyy="0.001" iyz="0.0" izz="0.001" />
    </inertial>
  </link>
  <joint name="right_rear_wheel_joint" type="continuous">
    <parent link="base_link"/>
    <child link="right_rear_wheel"/>
    <origin rpy="0 0 0" xyz="-0.13 -0.08 0.04"/>
    <axis xyz="0 1 0"/>
  </joint>

  <!-- imu -->
  <link name="imu_link"/>  
  <joint name="imu_joint" type="fixed">
    <parent link="base_link"/>
    <child link="imu_link"/>
    <origin xyz="0.0 0 0.04" rpy="0 0 0"/>
  </joint>

  <!-- scan -->
  <joint name="scan_joint" type="fixed">
    <parent link="base_link"/>
    <child link="base_scan"/>
    <origin xyz="0 0 0.1" rpy="0 0 0"/>
  </joint>

  <link name="base_scan">
    <inertial>
      <mass value="0.125" />
      <origin xyz="0 0 0.1" />
      <inertia ixx="0.001" ixy="0.0" ixz="0.0" iyy="0.001" iyz="0.0" izz="0.001" />
    </inertial>
  </link>

  <!-- left brush -->
  <link name="left_brush">
    <inertial>
      <mass value="1.0"/>
      <inertia ixx="0.001" ixy="0.0" ixz="0.0" iyy="0.001" iyz="0.0" izz="0.001" />
    </inertial>
  </link>
  <joint name="left_brush_joint" type="fixed">
    <parent link="base_link"/>
    <child link="left_brush"/>
    <origin rpy="0 0 0" xyz="0.16 0.1 0.01"/>
  </joint>

  <!-- right brush -->
  <link name="right_brush">
    <inertial>
      <mass value="1.0"/>
      <inertia ixx="0.001" ixy="0.0" ixz="0.0" iyy="0.001" iyz="0.0" izz="0.001" />
    </inertial>
  </link>
  <joint name="right_brush_joint" type="fixed">
    <parent link="base_link"/>
    <child link="right_brush"/>
    <origin rpy="0 0 0" xyz="0.16 -0.1 0.01"/>
  </joint>

</robot>
