<?xml version="1.0"?>
<sdf version="1.6">
  <world name="default">

    <include>
      <uri>model://ground_plane</uri>
    </include>

    <include>
      <uri>model://sun</uri>
    </include>

    <scene>
      <shadows>false</shadows>
    </scene>

    <gui fullscreen='0'>
      <camera name='user_camera'>
        <pose frame=''>0.319654 -0.235002 9.29441 0 1.5138 0.009599</pose>
        <view_controller>orbit</view_controller>
        <projection_type>perspective</projection_type>
      </camera>
    </gui>

    <physics type="ode">
      <real_time_update_rate>1000.0</real_time_update_rate>
      <max_step_size>0.001</max_step_size>
      <real_time_factor>1</real_time_factor>
      <ode>
        <solver>
          <type>quick</type>
          <iters>150</iters>
          <precon_iters>0</precon_iters>
          <sor>1.400000</sor>
          <use_dynamic_moi_rescaling>1</use_dynamic_moi_rescaling>
        </solver>
        <constraints>
          <cfm>0.00001</cfm>
          <erp>0.2</erp>
          <contact_max_correcting_vel>2000.000000</contact_max_correcting_vel>
          <contact_surface_layer>0.01000</contact_surface_layer>
        </constraints>
      </ode>
    </physics>

    <model name="turtlebot3_world">
      <static>1</static>
      <include>
        <uri>model://turtlebot3_world</uri>
      </include>
    </model>

    <model name="racecar">
      <pose>-2.0 -0.5 0.01 0.0 0.0 0.0</pose>

      <!-- base footprint -->
      <link name="base_footprint"/>

      <!-- base link -->
      <link name="base_link"/>
      <joint name="base_footprint_to_base_link" type="fixed">
        <parent>base_footprint</parent>
        <child>base_link</child>
        <pose>0 0 0 0 0 0</pose>
      </joint>

      <!-- Chassis -->
      <link name="chassis">
        <inertial>
          <pose>0 0 0.04 0 0 0</pose>
          <inertia>
            <ixx>0.0065806093333333334</ixx>
            <ixy>0.000</ixy>
            <ixz>0.000</ixz>
            <iyy>0.015488269333333332</iyy>
            <iyz>0.000</iyz>
            <izz>0.022022411999999995</izz>
          </inertia>
          <mass>3</mass>
        </inertial>
        <collision name="chassis_collision">
          <pose>0 0 0.04 0 0 0</pose>
          <geometry>
            <box>
              <size>0.01 0.01 0.01</size>
            </box>
          </geometry>
        </collision>
        <visual name="chassis_visual">
          <pose>0 0 0.04 0 0 0</pose>
          <geometry>
            <box>
              <size>0.26 0.16 0.02</size>
            </box>
          </geometry>
        </visual>
      </link>
      <joint name="base_link_to_chassis" type="fixed">
        <parent>base_link</parent>
        <child>chassis</child>
        <pose>0 0 0.04 0 0 0</pose>
      </joint>

      <!-- left front wheel link -->
      <link name="left_front_wheel">
        <inertial>
          <inertia>
            <ixx>0.001</ixx>
            <ixy>0.000</ixy>
            <ixz>0.000</ixz>
            <iyy>0.001</iyy>
            <iyz>0.000</iyz>
            <izz>0.001</izz>
          </inertia>
          <mass>1.0</mass>
        </inertial>
        <collision name="left_front_wheel_collision">
          <pose>0.13 0.08 0.04 -1.57 0 0</pose>
          <geometry>
            <cylinder>
              <length>0.04</length>
              <radius>0.04</radius>
            </cylinder>
          </geometry>
        </collision>
        <visual name="left_front_wheel_visual">
          <pose>0.13 0.08 0.04 -1.57 0 0</pose>
          <geometry>
            <cylinder>
              <length>0.04</length>
              <radius>0.04</radius>
            </cylinder>
          </geometry>
        </visual>
      </link>
      <joint name="left_front_wheel_joint" type="revolute">
        <parent>left_front_axle</parent>
        <child>left_front_wheel</child>
        <pose>0.13 0.08 0.04 0 0 0</pose>
        <axis>
          <xyz>0 1 0</xyz>
        </axis>
      </joint>
      <link name="left_front_axle">
        <inertial>
          <pose>0.13 0.08 0.04 0 0 0</pose>
          <inertia>
            <ixx>0.001</ixx>
            <ixy>0.000</ixy>
            <ixz>0.000</ixz>
            <iyy>0.001</iyy>
            <iyz>0.000</iyz>
            <izz>0.001</izz>
          </inertia>
          <mass>0.1</mass>
        </inertial>
      </link>
      <joint name="left_steering_joint" type="revolute">
        <parent>left_steering</parent>
        <child>left_front_axle</child>
        <pose>0.13 0.08 0.05 0 0 0</pose>
        <axis>
          <xyz>0 0 1</xyz>
        </axis>
      </joint>
      <link name="left_steering">
        <inertial>
          <pose>0.13 0.08 0.05 0 0 0</pose>
          <inertia>
            <ixx>0.001</ixx>
            <ixy>0.000</ixy>
            <ixz>0.000</ixz>
            <iyy>0.001</iyy>
            <iyz>0.000</iyz>
            <izz>0.001</izz>
          </inertia>
          <mass>0.1</mass>
        </inertial>
      </link>
      <joint name="left_joint" type="fixed">
        <parent>chassis</parent>
        <child>left_steering</child>
        <pose>0.13 0.08 0.05 0 0 0</pose>
      </joint>

      <!-- right front wheel link -->
      <link name="right_front_wheel">
        <inertial>
          <inertia>
            <ixx>0.001</ixx>
            <ixy>0.000</ixy>
            <ixz>0.000</ixz>
            <iyy>0.001</iyy>
            <iyz>0.000</iyz>
            <izz>0.001</izz>
          </inertia>
          <mass>1.0</mass>
        </inertial>
        <collision name="right_front_wheel_collision">
          <pose>0.13 -0.08 0.04 -1.57 0 0</pose>
          <geometry>
            <cylinder>
              <length>0.04</length>
              <radius>0.04</radius>
            </cylinder>
          </geometry>
        </collision>
        <visual name="right_front_wheel_visual">
          <pose>0.13 -0.08 0.04 -1.57 0 0</pose>
          <geometry>
            <cylinder>
              <length>0.04</length>
              <radius>0.04</radius>
            </cylinder>
          </geometry>
        </visual>
      </link>
      <joint name="right_front_wheel_joint" type="revolute">
        <parent>right_front_axle</parent>
        <child>right_front_wheel</child>
        <pose>0.13 -0.08 0.04 0 0 0</pose>
        <axis>
          <xyz>0 1 0</xyz>
        </axis>
      </joint>
      <link name="right_front_axle">
        <inertial>
          <pose>0.13 -0.08 0.04 0 0 0</pose>
          <inertia>
            <ixx>0.001</ixx>
            <ixy>0.000</ixy>
            <ixz>0.000</ixz>
            <iyy>0.001</iyy>
            <iyz>0.000</iyz>
            <izz>0.001</izz>
          </inertia>
          <mass>0.1</mass>
        </inertial>
      </link>
      <joint name="right_steering_joint" type="revolute">
        <parent>right_steering</parent>
        <child>right_front_axle</child>
        <pose>0.13 -0.08 0.05 0 0 0</pose>
        <axis>
          <xyz>0 0 1</xyz>
        </axis>
      </joint>
      <link name="right_steering">
        <inertial>
          <pose>0.13 -0.08 0.05 0 0 0</pose>
          <inertia>
            <ixx>0.001</ixx>
            <ixy>0.000</ixy>
            <ixz>0.000</ixz>
            <iyy>0.001</iyy>
            <iyz>0.000</iyz>
            <izz>0.001</izz>
          </inertia>
          <mass>0.1</mass>
        </inertial>
      </link>
      <joint name="right_joint" type="fixed">
        <parent>chassis</parent>
        <child>right_steering</child>
        <pose>0.13 -0.08 0.05 0 0 0</pose>
      </joint>

      <!-- steering joint -->
      <link name="steering"/>
      <joint name="steering_joint" type="revolute">
        <parent>chassis</parent>
        <child>steering</child>
        <pose>0.13 0 0.05 0 0 0</pose>
        <axis>
          <xyz>0 0 1</xyz>
        </axis>
      </joint>

      <!-- left rear wheel link -->
      <link name="left_rear_wheel">
        <inertial>
          <inertia>
            <ixx>0.001</ixx>
            <ixy>0.000</ixy>
            <ixz>0.000</ixz>
            <iyy>0.001</iyy>
            <iyz>0.000</iyz>
            <izz>0.001</izz>
          </inertia>
          <mass>1.0</mass>
        </inertial>
        <collision name="left_rear_wheel_collision">
          <pose>-0.13 0.08 0.04 -1.57 0 0</pose>
          <geometry>
            <cylinder>
              <length>0.04</length>
              <radius>0.04</radius>
            </cylinder>
          </geometry>
        </collision>
        <visual name="left_rear_wheel_visual">
          <pose>-0.13 0.08 0.04 -1.57 0 0</pose>
          <geometry>
            <cylinder>
              <length>0.04</length>
              <radius>0.04</radius>
            </cylinder>
          </geometry>
        </visual>
      </link>
      <joint name="left_rear_wheel_joint" type="revolute">
        <parent>chassis</parent>
        <child>left_rear_wheel</child>
        <pose>-0.13 0.08 0.04 -1.57 0 0</pose>
        <axis>
          <xyz>0 0 1</xyz>
        </axis>
      </joint>

      <!-- right front wheel link -->
      <link name="right_rear_wheel">
        <inertial>
          <inertia>
            <ixx>0.001</ixx>
            <ixy>0.000</ixy>
            <ixz>0.000</ixz>
            <iyy>0.001</iyy>
            <iyz>0.000</iyz>
            <izz>0.001</izz>
          </inertia>
          <mass>1.0</mass>
        </inertial>
        <collision name="right_rear_wheel_collision">
          <pose>-0.13 -0.08 0.04 1.57 0 0</pose>
          <geometry>
            <cylinder>
              <length>0.04</length>
              <radius>0.04</radius>
            </cylinder>
          </geometry>
        </collision>
        <visual name="right_rear_wheel_visual">
          <pose>-0.13 -0.08 0.04 1.57 0 0</pose>
          <geometry>
            <cylinder>
              <length>0.04</length>
              <radius>0.04</radius>
            </cylinder>
          </geometry>
        </visual>
      </link>
      <joint name="right_rear_wheel_joint" type="revolute">
        <parent>chassis</parent>
        <child>right_rear_wheel</child>
        <pose>-0.13 -0.08 0.04 1.57 0 0</pose>
        <axis>
          <xyz>0 0 1</xyz>
        </axis>
      </joint>

      <!-- ackermann drive -->
      <plugin name="racecar_ackermann_drive" filename="libgazebo_ros_ackermann_drive.so">

        <ros>
          <!-- <namespace>/tb3</namespace> -->
        </ros>

        <update_rate>30</update_rate>

        <!-- wheels -->
        <front_left_joint>left_front_wheel_joint</front_left_joint>
        <front_right_joint>right_front_wheel_joint</front_right_joint>
        <rear_left_joint>left_rear_wheel_joint</rear_left_joint>
        <rear_right_joint>right_rear_wheel_joint</rear_right_joint>
        <left_steering_joint>left_steering_joint</left_steering_joint>
        <right_steering_joint>right_steering_joint</right_steering_joint>
        <steering_wheel_joint>steering_joint</steering_wheel_joint>
        <!-- Max absolute steer angle for tyre in radians-->
        <!-- Any cmd_vel angular z greater than this would be capped -->
        <max_steer>0.6458</max_steer>
        <!-- Max absolute steering angle of steering wheel -->
        <max_steering_angle>7.85</max_steering_angle>
        <!-- Max absolute linear speed in m/s -->
        <max_speed>1.2</max_speed>
        <!-- PID tuning -->
        <left_steering_pid_gain>0.2 0 1</left_steering_pid_gain>
        <left_steering_i_range>0 0</left_steering_i_range>
        <right_steering_pid_gain>0.2 0 1</right_steering_pid_gain>
        <right_steering_i_range>0 0</right_steering_i_range>
        <linear_velocity_pid_gain>0.02 0 1</linear_velocity_pid_gain>
        <linear_velocity_i_range>0 0</linear_velocity_i_range>
        <!-- output -->
        <publish_odom>true</publish_odom>
        <publish_odom_tf>true</publish_odom_tf>
        <publish_wheel_tf>true</publish_wheel_tf>
        <publish_distance>true</publish_distance>
        <odometry_frame>odom</odometry_frame>
        <robot_base_frame>base_footprint</robot_base_frame>
      </plugin>





    </model>


  </world>
</sdf>
