<?xml version="1.0"?>
<sdf version="1.6">
  <world name="default">

    <include>
      <uri>model://ground_plane</uri>
    </include>

    <include>
      <uri>model://sun</uri>
    </include>

    <scene>
      <shadows>false</shadows>
    </scene>

    <gui fullscreen='0'>
      <camera name='user_camera'>
        <pose frame=''>0.319654 -0.235002 9.29441 0 1.5138 0.009599</pose>
        <view_controller>orbit</view_controller>
        <projection_type>perspective</projection_type>
      </camera>
    </gui>

    <physics type="ode">
      <real_time_update_rate>1000.0</real_time_update_rate>
      <max_step_size>0.001</max_step_size>
      <real_time_factor>1</real_time_factor>
      <ode>
        <solver>
          <type>quick</type>
          <iters>150</iters>
          <precon_iters>0</precon_iters>
          <sor>1.400000</sor>
          <use_dynamic_moi_rescaling>1</use_dynamic_moi_rescaling>
        </solver>
        <constraints>
          <cfm>0.00001</cfm>
          <erp>0.2</erp>
          <contact_max_correcting_vel>2000.000000</contact_max_correcting_vel>
          <contact_surface_layer>0.01000</contact_surface_layer>
        </constraints>
      </ode>
    </physics>

    <model name="turtlebot3_world">
      <static>1</static>
      <include>
        <uri>model://turtlebot3_world</uri>
      </include>
    </model>

    <model name="racecar">
      <pose>-2.0 -0.5 0.01 0.0 0.0 0.0</pose>

      <!-- base footprint -->
      <link name="base_footprint"/>

      <!-- base_link -->
      <link name="base_link">
        <inertial>
          <pose>0 0 0.04 0 0 0</pose>
          <!-- <inertia>
            <ixx>1.1</ixx>
            <ixy>0.000</ixy>
            <ixz>0.000</ixz>
            <iyy>1.1</iyy>
            <iyz>0.000</iyz>
            <izz>1.1</izz>
          </inertia> -->
          <mass>100</mass>
        </inertial>
        <collision name="base_link_collision">
          <pose>0 0 0.04 0 0 0</pose>
          <geometry>
            <box>
              <size>0.1 0.1 0.02</size>
            </box>
          </geometry>
        </collision>
        <visual name="base_link_visual">
          <pose>0 0 0.04 0 0 0</pose>
          <geometry>
            <box>
              <size>0.26 0.16 0.02</size>
            </box>
          </geometry>
        </visual>
      </link>
      <joint name="base_joint" type="fixed">
        <parent>base_footprint</parent>
        <child>base_link</child>
        <pose>0 0 0.04 0 0 0</pose>
      </joint>

      <!-- left front wheel link -->
      <link name="left_front_wheel">
        <inertial>
          <mass>1.0</mass>
        </inertial>
        <collision name="left_front_wheel_collision">
          <pose>0.13 0.08 0.04 -1.57 0 0</pose>
          <geometry>
            <cylinder>
              <length>0.04</length>
              <radius>0.04</radius>
            </cylinder>
          </geometry>
          <surface>
            <friction>
              <ode>
                <mu>1.1</mu>
                <mu2>1.1</mu2>
                <slip1>0.0</slip1>
                <slip2>0.0</slip2>
              </ode>
            </friction>
            <contact>
              <ode>
                <min_depth>0.001</min_depth>
                <kp>1e9</kp>
              </ode>
            </contact>
          </surface>
        </collision>
        <visual name="left_front_wheel_visual">
          <pose>0.13 0.08 0.04 -1.57 0 0</pose>
          <geometry>
            <cylinder>
              <length>0.04</length>
              <radius>0.04</radius>
            </cylinder>
          </geometry>
        </visual>
      </link>
      <joint name="left_front_wheel_joint" type="revolute">
        <parent>left_front_axle</parent>
        <child>left_front_wheel</child>
        <pose>0.13 0.08 0.04 0 0 0</pose>
        <axis>
          <xyz>0 1 0</xyz>
        </axis>
      </joint>
      <link name="left_front_axle">
        <inertial>
          <pose>0.13 0.08 0.04 0 0 0</pose>
          <mass>0.1</mass>
        </inertial>
      </link>
      <joint name="left_steering_joint" type="revolute">
        <parent>left_steering</parent>
        <child>left_front_axle</child>
        <pose>0.13 0.08 0.05 0 0 0</pose>
        <axis>
          <xyz>0 0 1</xyz>
        </axis>
      </joint>
      <link name="left_steering">
        <inertial>
          <pose>0.13 0.08 0.05 0 0 0</pose>
          <mass>0.1</mass>
        </inertial>
      </link>
      <joint name="left_joint" type="fixed">
        <parent>base_link</parent>
        <child>left_steering</child>
        <pose>0.13 0.08 0.05 0 0 0</pose>
      </joint>

      <!-- right front wheel link -->
      <link name="right_front_wheel">
        <inertial>
          <mass>1.0</mass>
        </inertial>
        <collision name="right_front_wheel_collision">
          <pose>0.13 -0.08 0.04 1.57 0 0</pose>
          <geometry>
            <cylinder>
              <length>0.04</length>
              <radius>0.04</radius>
            </cylinder>
          </geometry>
          <surface>
            <friction>
              <ode>
                <mu>1.1</mu>
                <mu2>1.1</mu2>
                <slip1>0.0</slip1>
                <slip2>0.0</slip2>
              </ode>
            </friction>
            <contact>
              <ode>
                <min_depth>0.001</min_depth>
                <kp>1e9</kp>
              </ode>
            </contact>
          </surface>
        </collision>
        <visual name="right_front_wheel_visual">
          <pose>0.13 -0.08 0.04 1.57 0 0</pose>
          <geometry>
            <cylinder>
              <length>0.04</length>
              <radius>0.04</radius>
            </cylinder>
          </geometry>
        </visual>
      </link>
      <joint name="right_front_wheel_joint" type="revolute">
        <parent>right_front_axle</parent>
        <child>right_front_wheel</child>
        <pose>0.13 -0.08 0.04 0 0 0</pose>
        <axis>
          <xyz>0 1 0</xyz>
        </axis>
      </joint>
      <link name="right_front_axle">
        <inertial>
          <pose>0.13 -0.08 0.04 0 0 0</pose>
          <mass>0.1</mass>
        </inertial>
      </link>
      <joint name="right_steering_joint" type="revolute">
        <parent>right_steering</parent>
        <child>right_front_axle</child>
        <pose>0.13 -0.08 0.05 0 0 0</pose>
        <axis>
          <xyz>0 0 1</xyz>
        </axis>
      </joint>
      <link name="right_steering">
        <inertial>
          <pose>0.13 -0.08 0.05 0 0 0</pose>
          <mass>0.1</mass>
        </inertial>
      </link>
      <joint name="right_joint" type="fixed">
        <parent>base_link</parent>
        <child>right_steering</child>
        <pose>0.13 -0.08 0.05 0 0 0</pose>
      </joint>

      <!-- front wheel link -->
      <!-- <link name="front_wheel">
        <inertial>
          <mass>1.0</mass>
        </inertial>
        <collision name="front_wheel_collision">
          <pose>0.13 0.0 0.04 -1.57 0 0</pose>
          <geometry>
            <cylinder>
              <length>0.04</length>
              <radius>0.04</radius>
            </cylinder>
          </geometry>
          <surface>
            <friction>
              <ode>
                <mu>1.1</mu>
                <mu2>1.1</mu2>
                <slip1>0.0</slip1>
                <slip2>0.0</slip2>
              </ode>
            </friction>
            <contact>
              <ode>
                <min_depth>0.001</min_depth>
                <kp>1e9</kp>
              </ode>
            </contact>
          </surface>
        </collision>
        <visual name="front_wheel_visual">
          <pose>0.13 0.0 0.04 -1.57 0 0</pose>
          <geometry>
            <cylinder>
              <length>0.04</length>
              <radius>0.04</radius>
            </cylinder>
          </geometry>
        </visual>
      </link>
      <joint name="front_wheel_joint" type="revolute">
        <parent>front_axle</parent>
        <child>front_wheel</child>
        <pose>0.13 0.0 0.04 0 0 0</pose>
        <axis>
          <xyz>0 1 0</xyz>
        </axis>
      </joint>
      <link name="front_axle">
        <inertial>
          <pose>0.13 0 0.04 0 0 0</pose>
          <mass>0.1</mass>
        </inertial>
      </link>
      <joint name="steering_joint" type="revolute">
        <parent>front_steering</parent>
        <child>front_axle</child>
        <pose>0.13 0.0 0.05 0 0 0</pose>
        <axis>
          <xyz>0 0 1</xyz>
        </axis>
      </joint>
      <link name="front_steering">
        <inertial>
          <pose>0.13 0 0.05 0 0 0</pose>
          <mass>0.1</mass>
        </inertial>
      </link>
      <joint name="front_joint" type="fixed">
        <parent>base_link</parent>
        <child>front_steering</child>
        <pose>0.13 0 0.05 0 0 0</pose>
      </joint> -->

      <!-- left rear wheel link -->
      <link name="left_rear_wheel">
        <inertial>
          <mass>1.0</mass>
        </inertial>
        <collision name="left_rear_wheel_collision">
          <pose>-0.13 0.08 0.04 -1.57 0 0</pose>
          <geometry>
            <cylinder>
              <length>0.04</length>
              <radius>0.04</radius>
            </cylinder>
          </geometry>
          <surface>
            <friction>
              <ode>
                <mu>1.1</mu>
                <mu2>1.1</mu2>
                <slip1>0.0</slip1>
                <slip2>0.0</slip2>
              </ode>
            </friction>
            <contact>
              <ode>
                <min_depth>0.001</min_depth>
                <kp>1e9</kp>
              </ode>
            </contact>
          </surface>
        </collision>
        <visual name="left_rear_wheel_visual">
          <pose>-0.13 0.08 0.04 -1.57 0 0</pose>
          <geometry>
            <cylinder>
              <length>0.04</length>
              <radius>0.04</radius>
            </cylinder>
          </geometry>
        </visual>
      </link>
      <joint name="left_rear_wheel_joint" type="revolute">
        <parent>base_link</parent>
        <child>left_rear_wheel</child>
        <pose>-0.13 0.08 0.04 0 0 0</pose>
        <axis>
          <xyz>0 1 0</xyz>
          <dynamics>
            <friction>18.0474092253</friction>
          </dynamics>
        </axis>
      </joint>

      <!-- right rear wheel link -->
      <link name="right_rear_wheel">
        <inertial>
          <mass>1.0</mass>
        </inertial>
        <collision name="right_rear_wheel_collision">
          <pose>-0.13 -0.08 0.04 1.57 0 0</pose>
          <geometry>
            <cylinder>
              <length>0.04</length>
              <radius>0.04</radius>
            </cylinder>
          </geometry>
          <surface>
            <friction>
              <ode>
                <mu>1.1</mu>
                <mu2>1.1</mu2>
                <slip1>0.0</slip1>
                <slip2>0.0</slip2>
              </ode>
            </friction>
            <contact>
              <ode>
                <min_depth>0.001</min_depth>
                <kp>1e9</kp>
              </ode>
            </contact>
          </surface>
        </collision>
        <visual name="right_rear_wheel_visual">
          <pose>-0.13 -0.08 0.04 1.57 0 0</pose>
          <geometry>
            <cylinder>
              <length>0.04</length>
              <radius>0.04</radius>
            </cylinder>
          </geometry>
        </visual>
      </link>
      <joint name="right_rear_wheel_joint" type="revolute">
        <parent>base_link</parent>
        <child>right_rear_wheel</child>
        <pose>-0.13 -0.08 0.04 0 0 0</pose>
        <axis>
          <xyz>0 1 0</xyz>
          <dynamics>
            <friction>18.0474092253</friction>
          </dynamics>
        </axis>
      </joint>

      <!-- left brush -->
      <link name="left_brush">
        <inertial>
          <mass>1.0</mass>
        </inertial>
        <visual name="left_brush_visual">
          <pose>0.16 0.1 0.02 0 0 0</pose>
          <geometry>
            <cylinder>
              <length>0.02</length>
              <radius>0.04</radius>
            </cylinder>
          </geometry>
        </visual>
      </link>
      <joint name="left_brush_joint" type="fixed">
        <parent>base_link</parent>
        <child>left_brush</child>
        <pose>0.16 0.1 0.01 0 0 0</pose>
      </joint>

      <!-- right brush -->
      <link name="right_brush">
        <inertial>
          <mass>1.0</mass>
        </inertial>
        <visual name="right_brush_visual">
          <pose>0.16 -0.1 0.02 0 0 0</pose>
          <geometry>
            <cylinder>
              <length>0.02</length>
              <radius>0.04</radius>
            </cylinder>
          </geometry>
        </visual>
      </link>
      <joint name="right_brush_joint" type="fixed">
        <parent>base_link</parent>
        <child>right_brush</child>
        <pose>0.16 -0.1 0.01 0 0 0</pose>
      </joint>

      <!-- ackermann drive -->
      <plugin name="racecar_ackermann_drive" filename="libgazebo_ros_ackermann_drive.so">

        <ros>
          <!-- <namespace>/tb3</namespace> -->
        </ros>

        <update_rate>100</update_rate>

        <!-- wheels -->
        <front_left_joint>left_front_wheel_joint</front_left_joint>
        <front_right_joint>right_front_wheel_joint</front_right_joint>
        <rear_left_joint>left_rear_wheel_joint</rear_left_joint>
        <rear_right_joint>right_rear_wheel_joint</rear_right_joint>
        <left_steering_joint>left_steering_joint</left_steering_joint>
        <right_steering_joint>right_steering_joint</right_steering_joint>
        <!-- <steering_wheel_joint>steering_joint</steering_wheel_joint> -->
        <!-- Max absolute steer angle for tyre in radians-->
        <!-- Any cmd_vel angular z greater than this would be capped -->
        <max_steer>0.6458</max_steer>
        <!-- Max absolute steering angle of steering wheel -->
        <max_steering_angle>7.85</max_steering_angle>
        <!-- Max absolute linear speed in m/s -->
        <max_speed>1.2</max_speed>
        <!-- PID tuning -->
        <left_steering_pid_gain>800 1 5</left_steering_pid_gain>
        <left_steering_i_range>0 0</left_steering_i_range>
        <right_steering_pid_gain>800 1 5</right_steering_pid_gain>
        <right_steering_i_range>0 0</right_steering_i_range>
        <linear_velocity_pid_gain>1000 0 3</linear_velocity_pid_gain>
        <linear_velocity_i_range>0 0</linear_velocity_i_range>
        <!-- output -->
        <publish_odom>true</publish_odom>
        <publish_odom_tf>true</publish_odom_tf>
        <publish_wheel_tf>false</publish_wheel_tf>
        <publish_distance>false</publish_distance>
        <odometry_topic>odom</odometry_topic>
        <odometry_frame>odom</odometry_frame>
        <robot_base_frame>base_footprint</robot_base_frame>
      </plugin>

      <plugin name="racecar_joint_state" filename="libgazebo_ros_joint_state_publisher.so">
        <ros>
            <remapping>~/out:=joint_states</remapping>
        </ros>
        <update_rate>30</update_rate>
        <joint_name>left_front_wheel_joint</joint_name>
        <joint_name>right_front_wheel_joint</joint_name>
        <joint_name>left_rear_wheel_joint</joint_name>
        <joint_name>right_rear_wheel_joint</joint_name>
        <joint_name>left_steering_joint</joint_name>
        <joint_name>right_steering_joint</joint_name>
        <!-- <joint_name>steering_joint</joint_name> -->
      </plugin>

      <link name="base_scan">
        <inertial>
          <pose>0 0 0.1 0 0 0</pose>
          <mass>0.125</mass>
        </inertial>
        <visual name="lidar_sensor_visual">
          <pose>0 0 0.1 0 0 0</pose>
          <geometry>
            <cylinder>
              <length>0.002</length>
              <radius>0.01</radius>
            </cylinder>
          </geometry>
        </visual>
        <sensor name="hls_lfcd_lds" type="ray">
          <always_on>true</always_on>
          <visualize>true</visualize>
          <pose>0 0 0.1 0 0 0</pose>
          <update_rate>5</update_rate>
          <ray>
            <scan>
              <horizontal>
                <samples>360</samples>
                <resolution>1.000000</resolution>
                <min_angle>0.000000</min_angle>
                <max_angle>6.280000</max_angle>
              </horizontal>
            </scan>
            <range>
              <min>0.120000</min>
              <max>3.5</max>
              <resolution>0.015000</resolution>
            </range>
            <noise>
              <type>gaussian</type>
              <mean>0.0</mean>
              <stddev>0.01</stddev>
            </noise>
          </ray>
          <plugin name="racecar_laserscan" filename="libgazebo_ros_ray_sensor.so">
            <ros>
                <!-- <namespace>/tb3</namespace> -->
                <remapping>~/out:=scan</remapping>
            </ros>
            <output_type>sensor_msgs/LaserScan</output_type>
            <frame_name>base_scan</frame_name>
          </plugin>
        </sensor>
      </link>
      <joint name="lidar_joint" type="fixed">
        <parent>base_link</parent>
        <child>base_scan</child>
        <pose>0 0 0.1 0 0 0</pose>
      </joint>
    </model>


  </world>
</sdf>
